Workbook

Sheet README
A1: DIH Risk Dataset — Handover Workbook
A3: Purpose
A4: Static reference dataset the DIH tech team implements the risk-calculation pipeline against, until the live data flows (Google Dynamic World, MoA livestock census, IPC feed, DWA water demand) are wired in. Every value in the blue-fill cells is meant to be replaced by real data at ingestion time; the formulas in the black cells compute the final risk score and class per Inkhundla.
A6: How to use this workbook
A7: 1. Read the Methodology tab. It contains the formulas, the rescale tables and the risk-class bands that every downstream calculation depends on.
A8: 2. Fill the blue-highlighted cells on each of the input tabs (Inkhundla_master, Exposure_*, Vulnerability_IPC, Hazard_current_cycle). Rows are pre-numbered 1–59; the Inkhundla name in column B must match exactly across every tab.
A9: 3. The Risk_expected tab pulls values from the input tabs and computes the expected risk score + class for each Inkhundla. Do not edit its cells — treat them as the verification target for the pipeline implementation.
A10: 4. Field_dictionary is the machine-readable spec — column, unit, source, cadence and whether the field is currently static or wired to a live pipeline. Keep it in sync as fields move from static → live.
A12: Cell colour legend
A13: • Blue text on yellow fill → input cell, user-editable
A14: • Green text → cross-sheet lookup or reference (do not edit)
A15: • Black text → formula (do not edit)
... A23: Reference document: DIH-Operational-SOP-v1.docx §4.5

Sheet Methodology
A1: Risk methodology — reference tables
A2: Formulas and rescale tables that drive every calculation in this workbook. See DIH-Operational-SOP-v1.docx §4.5 for the full narrative.
A4: Risk formula
A5: Risk(i) = Hazard(i) × Exposure(i) × Vulnerability(i)
A6: All three components lie in [0, 1] so the product also lies in [0, 1]. A multiplicative form is used so that risk collapses to zero whenever any single component is absent (no hazard, no exposure, or no vulnerability = no active risk).
A8: Hazard rescale table — validated D-class → H value
A9: Equal 0.20 steps across the six-class NDMC scale.
A10: D-class | B10: H value | D10: Description
A11: None | B11: 0 | D11: No drought signal
A12: D0 | B12: 0.2 | D12: Abnormally dry
A13: D1 | B13: 0.4 | D13: Moderate drought
A14: D2 | B14: 0.6 | D14: Severe drought
A15: D3 | B15: 0.8 | D15: Extreme drought
A16: D4 | B16: 1 | D16: Exceptional drought
A19: IPC vulnerability rescale table — phase → V value
A20: Non-linear because IPC severity is non-linear. Phase 1 is deliberately non-zero so that a severe hazard in a currently food-secure Inkhundla is not silenced.
A21: IPC phase | B21: V value | D21: Description
A22: 1 | B22: 0.1 | D22: Minimal / None
A23: 2 | B23: 0.3 | D23: Stressed
A24: 3 | B24: 0.6 | D24: Crisis
A25: 4 | B25: 0.85 | D25: Emergency
A26: 5 | B26: 1 | D26: Famine
A29: Risk-class bands
A30: Cut-offs used for map rendering and to match Recommended Mitigation Actions. The number of Inkhundla in each class will vary from cycle to cycle — this is intended.
A31: Threshold ≥ | B31: Class | D31: Operational implication
A32: 0.5 | B32: Very High | D32: Immediate response; priority resource allocation
A33: 0.3 | B33: High | D33: Response planning; activate contingency arrangements
A34: 0.15 | B34: Moderate | D34: Monitor and prepare; early-warning triggers active
A35: 0 | B35: Low | D35: Routine monitoring only
A38: Exposure composition
A39: Exposure(i) = arithmetic mean of the four sub-indicators listed below, each min-max normalised across the 59 Tinkhundla within the current cycle. Until water demand methodology is agreed with DWA, the composite is computed on the remaining three sub-indicators at 1/3 weight each; the Risk_expected sheet averages non-blank values so this behaviour is automatic.
A40: Sub-indicator | B40: Weight (when all 4 present) | C40: Weight (interim, 3 present) | D40: Normalisation method
A41: Land use — DVI-agri | B41: 0.25 | C41: 1/3 ≈ 0.333 | D41: Dynamic World reclass → agri-mask → polygon mean → min-max across 59 Tinkhundla
A42: Water demand | B42: 0.25 | C42: 1/3 ≈ 0.333 | D42: min-max of inkhundla water demand across 59 tinkhundla
A43: Population | B43: 0.25 | C43: 1/3 ≈ 0.333 | D43: Min-max of Inkhundla population count across 59 Tinkhundla
A44: Cattle count | B44: 0.25 | C44: 1/3 ≈ 0.333 | D44: Min-max of Inkhundla cattle count across 59 Tinkhundla
A47: Land-cover DVI weights (Dynamic World reclass, feeds DVI-agri)
A48: Per-pixel weights applied before the agricultural mask and zonal aggregation. Kept here for reference; DVI-agri values arrive at this workbook already computed per Inkhundla.
A49: Land-cover class | B49: DVI weight | D49: Note
A50: Cropland | B50: 0.9 | D50: Rain-fed crops — highest drought sensitivity
...

Sheet Inkhundla_master
A1: Inkhundla master — Canonical list of 59 Tinkhundla. Blue cells are user-fillable. Names in column B are the join key on every other sheet — spell them consistently.
A2: # | B2: Inkhundla name | C2: Region | D2: Agro-eco zone | E2: Area (km²) | F2: Tinkhundla ID | G2: Notes
A3: 1 | B3: Hhukwini | C3: Hhohho | D3: Highveld | E3: 1.8592461e+08 | F3: SWZ001001
A4: 2 | B4: Lobamba | C4: Hhohho | D4: Highveld | E4: 127375762 | F4: SWZ001002
A5: 3 | B5: Madlangempisi | C5: Hhohho | D5: Highveld | E5: 4.0943273e+08 | F5: SWZ001003
A6: 4 | B6: Maphalaleni | C6: Hhohho | D6: Highveld | E6: 3.5828349e+08 | F6: SWZ001004
A7: 5 | B7: Mayiwane | C7: Hhohho | D7: Western Lowveld | E7: 2.1237139e+08 | F7: SWZ001005
A8: 6 | B8: Mbabane East | C8: Hhohho | D8: Highveld | E8: 1.1153357e+08 | F8: SWZ001006
A9: 7 | B9: Mbabane West | C9: Hhohho | D9: Highveld | E9: 25864804 | F9: SWZ001007
A10: 8 | B10: Mhlangatane | C10: Hhohho | D10: Western Lowveld | E10: 2.1755162e+08 | F10: SWZ001008
A11: 9 | B11: Ndzingeni | C11: Hhohho | D11: Highveld | E11: 3.8943287e+08 | F11: SWZ001010
A12: 10 | B12: Nkhaba | C12: Hhohho | D12: Highveld | E12: 3.7346938e+08 | F12: SWZ001011
A13: 11 | B13: Motshane | C13: Hhohho | D13: Highveld | E13: 1.9975538e+08 | F13: SWZ001009
A14: 12 | B14: Ntfonjeni | C14: Hhohho | D14: Highveld | E14: 3.84477e+08 | F14: SWZ001012
... A61: 59 | B61: Zombodze Emuva | C61: Shiselweni | D61: Highveld | E61: 1.5174847e+08 | F61: SWZ004015

Sheet Exposure_LandUse
A1: Exposure · Land use (DVI-agri) — One row per Inkhundla. Fill DVI-agri (polygon mean of the masked DVI raster, typical range 0.55–0.90). Column D auto-normalises across the 59 rows.
A2: # | B2: Inkhundla name | C2: Inkhundla ID | D2: DVI-agri (raw) | E2: Normalised (0–1) | F2: Source | G2: Reference date | H2: Notes
A3: 1 | B3: Hhukwini | C3: SWZ001001 | D3: 0.59866429 | E3: =IF(OR(D3="",COUNT($D$3:$D$61)<2),"",(D3-MIN($D$3:$D$61))/(MAX($D$3:$D$61)-MIN($D$3:$D$61))) -> 0.068990692 | F3: dynamic world | G3: 46225
A4: 2 | B4: Lobamba | C4: SWZ001002 | D4: 0.63646842 | E4: =IF(OR(D4="",COUNT($D$3:$D$61)<2),"",(D4-MIN($D$3:$D$61))/(MAX($D$3:$D$61)-MIN($D$3:$D$61))) -> 0.21340275 | F4: dynamic world | G4: 46225
A5: 3 | B5: Madlangempisi | C5: SWZ001003 | D5: 0.62133223 | E5: =IF(OR(D5="",COUNT($D$3:$D$61)<2),"",(D5-MIN($D$3:$D$61))/(MAX($D$3:$D$61)-MIN($D$3:$D$61))) -> 0.15558239 | F5: dynamic world | G5: 46225
A6: 4 | B6: Maphalaleni | C6: SWZ001004 | D6: 0.61717743 | E6: =IF(OR(D6="",COUNT($D$3:$D$61)<2),"",(D6-MIN($D$3:$D$61))/(MAX($D$3:$D$61)-MIN($D$3:$D$61))) -> 0.13971104 | F6: dynamic world | G6: 46225
A7: 5 | B7: Mayiwane | C7: SWZ001005 | D7: 0.58985622 | E7: =IF(OR(D7="",COUNT($D$3:$D$61)<2),"",(D7-MIN($D$3:$D$61))/(MAX($D$3:$D$61)-MIN($D$3:$D$61))) -> 0.035343815 | F7: dynamic world | G7: 46225
A8: 6 | B8: Mbabane East | C8: SWZ001006 | D8: 0.58671545 | E8: =IF(OR(D8="",COUNT($D$3:$D$61)<2),"",(D8-MIN($D$3:$D$61))/(MAX($D$3:$D$61)-MIN($D$3:$D$61))) -> 0.023346038 | F8: dynamic world | G8: 46225
A9: 7 | B9: Mbabane West | C9: SWZ001007 | D9: 0.62532483 | E9: =IF(OR(D9="",COUNT($D$3:$D$61)<2),"",(D9-MIN($D$3:$D$61))/(MAX($D$3:$D$61)-MIN($D$3:$D$61))) -> 0.17083417 | F9: dynamic world | G9: 46225
A10: 8 | B10: Mhlangatane | C10: SWZ001008 | D10: 0.65612174 | E10: =IF(OR(D10="",COUNT($D$3:$D$61)<2),"",(D10-MIN($D$3:$D$61))/(MAX($D$3:$D$61)-MIN($D$3:$D$61))) -> 0.28847857 | F10: dynamic world | G10: 46225
A11: 9 | B11: Ndzingeni | C11: SWZ001010 | D11: 0.60136398 | E11: =IF(OR(D11="",COUNT($D$3:$D$61)<2),"",(D11-MIN($D$3:$D$61))/(MAX($D$3:$D$61)-MIN($D$3:$D$61))) -> 0.07930352 | F11: dynamic world | G11: 46225
A12: 10 | B12: Nkhaba | C12: SWZ001011 | D12: 0.61900571 | E12: =IF(OR(D12="",COUNT($D$3:$D$61)<2),"",(D12-MIN($D$3:$D$61))/(MAX($D$3:$D$61)-MIN($D$3:$D$61))) -> 0.14669507 | F12: dynamic world | G12: 46225
A13: 11 | B13: Motshane | C13: SWZ001009 | D13: 0.63052003 | E13: =IF(OR(D13="",COUNT($D$3:$D$61)<2),"",(D13-MIN($D$3:$D$61))/(MAX($D$3:$D$61)-MIN($D$3:$D$61))) -> 0.19067987 | F13: dynamic world | G13: 46225
A14: 12 | B14: Ntfonjeni | C14: SWZ001012 | D14: 0.61731784 | E14: =IF(OR(D14="",COUNT($D$3:$D$61)<2),"",(D14-MIN($D$3:$D$61))/(MAX($D$3:$D$61)-MIN($D$3:$D$61))) -> 0.14024738 | F14: dynamic world | G14: 46225
... A61: 59 | B61: Zombodze Emuva | C61: SWZ004015 | D61: 0.62400501 | E61: =IF(OR(D61="",COUNT($D$3:$D$61)<2),"",(D61-MIN($D$3:$D$61))/(MAX($D$3:$D$61)-MIN($D$3:$D$61))) -> 0.16579242 | F61: dynamic world | G61: 46225

Sheet Exposure_Population
A1: Exposure · Population — One row per Inkhundla. Fill population count. Column D auto-normalises across the 59 rows.
A2: # | B2: Inkhundla name | C2: Inkhundla ID | D2: Population count | E2: Normalised (0–1) | F2: Source | G2: Reference year | H2: Notes
A3: 1 | B3: Hhukwini | C3: SWZ001001 | D3: 13992.452 | E3: =IF(OR(C3="",COUNT($D$3:$D$61)<2),"",(D3-MIN($D$3:$D$61))/(MAX($D$3:$D$61)-MIN($D$3:$D$61))) -> 0.18343748 | F3: world pop
A4: 2 | B4: Lobamba | C4: SWZ001002 | D4: 40431.958 | E4: =IF(OR(C4="",COUNT($D$3:$D$61)<2),"",(D4-MIN($D$3:$D$61))/(MAX($D$3:$D$61)-MIN($D$3:$D$61))) -> 0.9242977 | F4: world pop
A5: 3 | B5: Madlangempisi | C5: SWZ001003 | D5: 36796.663 | E5: =IF(OR(C5="",COUNT($D$3:$D$61)<2),"",(D5-MIN($D$3:$D$61))/(MAX($D$3:$D$61)-MIN($D$3:$D$61))) -> 0.82243325 | F5: world pop
A6: 4 | B6: Maphalaleni | C6: SWZ001004 | D6: 17229.4 | E6: =IF(OR(C6="",COUNT($D$3:$D$61)<2),"",(D6-MIN($D$3:$D$61))/(MAX($D$3:$D$61)-MIN($D$3:$D$61))) -> 0.27413987 | F6: world pop
A7: 5 | B7: Mayiwane | C7: SWZ001005 | D7: 19996.005 | E7: =IF(OR(C7="",COUNT($D$3:$D$61)<2),"",(D7-MIN($D$3:$D$61))/(MAX($D$3:$D$61)-MIN($D$3:$D$61))) -> 0.35166279 | F7: world pop
A8: 6 | B8: Mbabane East | C8: SWZ001006 | D8: 43133.59 | E8: =IF(OR(C8="",COUNT($D$3:$D$61)<2),"",(D8-MIN($D$3:$D$61))/(MAX($D$3:$D$61)-MIN($D$3:$D$61))) -> 1 | F8: world pop
A9: 7 | B9: Mbabane West | C9: SWZ001007 | D9: 20411.881 | E9: =IF(OR(C9="",COUNT($D$3:$D$61)<2),"",(D9-MIN($D$3:$D$61))/(MAX($D$3:$D$61)-MIN($D$3:$D$61))) -> 0.36331602 | F9: world pop
A10: 8 | B10: Mhlangatane | C10: SWZ001008 | D10: 28843.823 | E10: =IF(OR(C10="",COUNT($D$3:$D$61)<2),"",(D10-MIN($D$3:$D$61))/(MAX($D$3:$D$61)-MIN($D$3:$D$61))) -> 0.59958709 | F10: world pop
A11: 9 | B11: Ndzingeni | C11: SWZ001010 | D11: 25758.256 | E11: =IF(OR(C11="",COUNT($D$3:$D$61)<2),"",(D11-MIN($D$3:$D$61))/(MAX($D$3:$D$61)-MIN($D$3:$D$61))) -> 0.51312656 | F11: world pop
A12: 10 | B12: Nkhaba | C12: SWZ001011 | D12: 20771.714 | E12: =IF(OR(C12="",COUNT($D$3:$D$61)<2),"",(D12-MIN($D$3:$D$61))/(MAX($D$3:$D$61)-MIN($D$3:$D$61))) -> 0.37339889 | F12: world pop
A13: 11 | B13: Motshane | C13: SWZ001009 | D13: 31662.238 | E13: =IF(OR(C13="",COUNT($D$3:$D$61)<2),"",(D13-MIN($D$3:$D$61))/(MAX($D$3:$D$61)-MIN($D$3:$D$61))) -> 0.67856177 | F13: world pop
A14: 12 | B14: Ntfonjeni | C14: SWZ001012 | D14: 26457.733 | E14: =IF(OR(C14="",COUNT($D$3:$D$61)<2),"",(D14-MIN($D$3:$D$61))/(MAX($D$3:$D$61)-MIN($D$3:$D$61))) -> 0.53272656 | F14: world pop
... A61: 59 | B61: Zombodze Emuva | C61: SWZ004015 | D61: 15065.685 | E61: =IF(OR(C61="",COUNT($D$3:$D$61)<2),"",(D61-MIN($D$3:$D$61))/(MAX($D$3:$D$61)-MIN($D$3:$D$61))) -> 0.21351051 | F61: world pop

Sheet Exposure_Cattle
A1: Exposure · Cattle count — One row per Inkhundla. Fill cattle count (MoA livestock census). Column D auto-normalises across the 59 rows.
A2: # | B2: Inkhundla name | C2: Cattle count | D2: Normalised (0–1) | E2: Source | F2: Reference year | G2: Notes
A3: 1 | D3: =IF(OR(C3="",COUNT($C$3:$C$61)<2),"",(C3-MIN($C$3:$C$61))/(MAX($C$3:$C$61)-MIN($C$3:$C$61)))
A4: 2 | D4: =IF(OR(C4="",COUNT($C$3:$C$61)<2),"",(C4-MIN($C$3:$C$61))/(MAX($C$3:$C$61)-MIN($C$3:$C$61)))
A5: 3 | D5: =IF(OR(C5="",COUNT($C$3:$C$61)<2),"",(C5-MIN($C$3:$C$61))/(MAX($C$3:$C$61)-MIN($C$3:$C$61)))
A6: 4 | D6: =IF(OR(C6="",COUNT($C$3:$C$61)<2),"",(C6-MIN($C$3:$C$61))/(MAX($C$3:$C$61)-MIN($C$3:$C$61)))
A7: 5 | D7: =IF(OR(C7="",COUNT($C$3:$C$61)<2),"",(C7-MIN($C$3:$C$61))/(MAX($C$3:$C$61)-MIN($C$3:$C$61)))
A8: 6 | D8: =IF(OR(C8="",COUNT($C$3:$C$61)<2),"",(C8-MIN($C$3:$C$61))/(MAX($C$3:$C$61)-MIN($C$3:$C$61)))
A9: 7 | D9: =IF(OR(C9="",COUNT($C$3:$C$61)<2),"",(C9-MIN($C$3:$C$61))/(MAX($C$3:$C$61)-MIN($C$3:$C$61)))
A10: 8 | D10: =IF(OR(C10="",COUNT($C$3:$C$61)<2),"",(C10-MIN($C$3:$C$61))/(MAX($C$3:$C$61)-MIN($C$3:$C$61)))
A11: 9 | D11: =IF(OR(C11="",COUNT($C$3:$C$61)<2),"",(C11-MIN($C$3:$C$61))/(MAX($C$3:$C$61)-MIN($C$3:$C$61)))
A12: 10 | D12: =IF(OR(C12="",COUNT($C$3:$C$61)<2),"",(C12-MIN($C$3:$C$61))/(MAX($C$3:$C$61)-MIN($C$3:$C$61)))
A13: 11 | D13: =IF(OR(C13="",COUNT($C$3:$C$61)<2),"",(C13-MIN($C$3:$C$61))/(MAX($C$3:$C$61)-MIN($C$3:$C$61)))
A14: 12 | D14: =IF(OR(C14="",COUNT($C$3:$C$61)<2),"",(C14-MIN($C$3:$C$61))/(MAX($C$3:$C$61)-MIN($C$3:$C$61)))
... A61: 59 | D61: =IF(OR(C61="",COUNT($C$3:$C$61)<2),"",(C61-MIN($C$3:$C$61))/(MAX($C$3:$C$61)-MIN($C$3:$C$61)))

Sheet Exposure_WaterDemand
A1: Exposure · Water demand — PENDING (methodology TBD with DWA) — Placeholder. Until DWA agrees a methodology, leave column C blank. The Risk_expected sheet averages non-blank exposure components, so the composite will use 3 sub-indicators at 1/3 weight each while this sheet is empty.
A2: # | B2: Inkhundla name | C2: Water demand (raw) | D2: Normalised (0–1) | E2: Source | F2: Reference date | G2: Notes
A3: 1 | D3: =IF(OR(C3="",COUNT($C$3:$C$61)<2),"",(C3-MIN($C$3:$C$61))/(MAX($C$3:$C$61)-MIN($C$3:$C$61)))
A4: 2 | D4: =IF(OR(C4="",COUNT($C$3:$C$61)<2),"",(C4-MIN($C$3:$C$61))/(MAX($C$3:$C$61)-MIN($C$3:$C$61)))
A5: 3 | D5: =IF(OR(C5="",COUNT($C$3:$C$61)<2),"",(C5-MIN($C$3:$C$61))/(MAX($C$3:$C$61)-MIN($C$3:$C$61)))
A6: 4 | D6: =IF(OR(C6="",COUNT($C$3:$C$61)<2),"",(C6-MIN($C$3:$C$61))/(MAX($C$3:$C$61)-MIN($C$3:$C$61)))
A7: 5 | D7: =IF(OR(C7="",COUNT($C$3:$C$61)<2),"",(C7-MIN($C$3:$C$61))/(MAX($C$3:$C$61)-MIN($C$3:$C$61)))
A8: 6 | D8: =IF(OR(C8="",COUNT($C$3:$C$61)<2),"",(C8-MIN($C$3:$C$61))/(MAX($C$3:$C$61)-MIN($C$3:$C$61)))
A9: 7 | D9: =IF(OR(C9="",COUNT($C$3:$C$61)<2),"",(C9-MIN($C$3:$C$61))/(MAX($C$3:$C$61)-MIN($C$3:$C$61)))
A10: 8 | D10: =IF(OR(C10="",COUNT($C$3:$C$61)<2),"",(C10-MIN($C$3:$C$61))/(MAX($C$3:$C$61)-MIN($C$3:$C$61)))
A11: 9 | D11: =IF(OR(C11="",COUNT($C$3:$C$61)<2),"",(C11-MIN($C$3:$C$61))/(MAX($C$3:$C$61)-MIN($C$3:$C$61)))
A12: 10 | D12: =IF(OR(C12="",COUNT($C$3:$C$61)<2),"",(C12-MIN($C$3:$C$61))/(MAX($C$3:$C$61)-MIN($C$3:$C$61)))
A13: 11 | D13: =IF(OR(C13="",COUNT($C$3:$C$61)<2),"",(C13-MIN($C$3:$C$61))/(MAX($C$3:$C$61)-MIN($C$3:$C$61)))
A14: 12 | D14: =IF(OR(C14="",COUNT($C$3:$C$61)<2),"",(C14-MIN($C$3:$C$61))/(MAX($C$3:$C$61)-MIN($C$3:$C$61)))
... A61: 59 | D61: =IF(OR(C61="",COUNT($C$3:$C$61)<2),"",(C61-MIN($C$3:$C$61))/(MAX($C$3:$C$61)-MIN($C$3:$C$61)))

Sheet Vulnerability_IPC
A1: Vulnerability · IPC Acute Food Insecurity phase — One row per Inkhundla. Fill the IPC phase (1–5). Column D auto-maps to the V value via the Methodology · IPC rescale table.
A2: # | B2: Inkhundla name | C2: Inkhudnla ID | D2: IPC phase (1–5) | E2: V value | F2: Publication date | G2: Source | H2: Notes
A3: 1 | B3: Hhukwini | C3: SWZ001001 | D3: 2 | E3: =IFERROR(VLOOKUP(D3, Methodology!$A$22:$B$26, 2, FALSE()), "") -> 0.3
A4: 2 | B4: Lobamba | C4: SWZ001002 | D4: 2 | E4: =IFERROR(VLOOKUP(D4, Methodology!$A$22:$B$26, 2, FALSE()), "") -> 0.3
A5: 3 | B5: Madlangempisi | C5: SWZ001003 | D5: 3 | E5: =IFERROR(VLOOKUP(D5, Methodology!$A$22:$B$26, 2, FALSE()), "") -> 0.6
A6: 4 | B6: Maphalaleni | C6: SWZ001004 | D6: 2 | E6: =IFERROR(VLOOKUP(D6, Methodology!$A$22:$B$26, 2, FALSE()), "") -> 0.3
A7: 5 | B7: Mayiwane | C7: SWZ001005 | D7: 3 | E7: =IFERROR(VLOOKUP(D7, Methodology!$A$22:$B$26, 2, FALSE()), "") -> 0.6
A8: 6 | B8: Mbabane East | C8: SWZ001006 | D8: 2 | E8: =IFERROR(VLOOKUP(D8, Methodology!$A$22:$B$26, 2, FALSE()), "") -> 0.3
A9: 7 | B9: Mbabane West | C9: SWZ001007 | D9: 2 | E9: =IFERROR(VLOOKUP(D9, Methodology!$A$22:$B$26, 2, FALSE()), "") -> 0.3
A10: 8 | B10: Mhlangatane | C10: SWZ001008 | D10: 3 | E10: =IFERROR(VLOOKUP(D10, Methodology!$A$22:$B$26, 2, FALSE()), "") -> 0.6
A11: 9 | B11: Ndzingeni | C11: SWZ001010 | D11: 2 | E11: =IFERROR(VLOOKUP(D11, Methodology!$A$22:$B$26, 2, FALSE()), "") -> 0.3
A12: 10 | B12: Nkhaba | C12: SWZ001011 | D12: 2 | E12: =IFERROR(VLOOKUP(D12, Methodology!$A$22:$B$26, 2, FALSE()), "") -> 0.3
A13: 11 | B13: Motshane | C13: SWZ001009 | D13: 2 | E13: =IFERROR(VLOOKUP(D13, Methodology!$A$22:$B$26, 2, FALSE()), "") -> 0.3
A14: 12 | B14: Ntfonjeni | C14: SWZ001012 | D14: 2 | E14: =IFERROR(VLOOKUP(D14, Methodology!$A$22:$B$26, 2, FALSE()), "") -> 0.3
... A61: 59 | B61: Zombodze Emuva | C61: SWZ004015 | D61: 2 | E61: =IFERROR(VLOOKUP(D61, Methodology!$A$22:$B$26, 2, FALSE()), "") -> 0.3

Sheet Hazard_current_cycle
A1: Hazard · validated D-class for the current cycle — One row per Inkhundla. Fill the validated D-class (None · D0 · D1 · D2 · D3 · D4). Column E auto-maps to the H value via the Methodology · Hazard rescale table.
A2: # | B2: Inkhundla name | C2: Cycle month | D2: Validated D-class | E2: H value | F2: Validated on (date) | G2: Notes
A3: 1 | E3: =IFERROR(VLOOKUP(D3, Methodology!$A$11:$B$16, 2, FALSE()), "")
A4: 2 | E4: =IFERROR(VLOOKUP(D4, Methodology!$A$11:$B$16, 2, FALSE()), "")
A5: 3 | E5: =IFERROR(VLOOKUP(D5, Methodology!$A$11:$B$16, 2, FALSE()), "")
A6: 4 | E6: =IFERROR(VLOOKUP(D6, Methodology!$A$11:$B$16, 2, FALSE()), "")
A7: 5 | E7: =IFERROR(VLOOKUP(D7, Methodology!$A$11:$B$16, 2, FALSE()), "")
A8: 6 | E8: =IFERROR(VLOOKUP(D8, Methodology!$A$11:$B$16, 2, FALSE()), "")
A9: 7 | E9: =IFERROR(VLOOKUP(D9, Methodology!$A$11:$B$16, 2, FALSE()), "")
A10: 8 | E10: =IFERROR(VLOOKUP(D10, Methodology!$A$11:$B$16, 2, FALSE()), "")
A11: 9 | E11: =IFERROR(VLOOKUP(D11, Methodology!$A$11:$B$16, 2, FALSE()), "")
A12: 10 | E12: =IFERROR(VLOOKUP(D12, Methodology!$A$11:$B$16, 2, FALSE()), "")
A13: 11 | E13: =IFERROR(VLOOKUP(D13, Methodology!$A$11:$B$16, 2, FALSE()), "")
A14: 12 | E14: =IFERROR(VLOOKUP(D14, Methodology!$A$11:$B$16, 2, FALSE()), "")
... A61: 59 | E61: =IFERROR(VLOOKUP(D61, Methodology!$A$11:$B$16, 2, FALSE()), "")

Sheet Risk_expected
A1: Risk_expected — verification target for the pipeline — This sheet is 100% formula. Fill Inkhundla name in column B (or leave blank to derive from Inkhundla_master). Every other column pulls from the input tabs. The tech team's pipeline should reproduce column J and column K exactly.
A2: # | B2: Inkhundla name | C2: Hazard (H) | D2: Land use (norm) | E2: Population (norm) | F2: Cattle (norm) | G2: Water demand (norm) | H2: Exposure (E) | I2: Vulnerability (V) | J2: Risk score | K2: Risk class
A3: 1 | B3: Hhukwini | C3: =IFERROR(INDEX(Hazard_current_cycle!$E$3:$E$61, MATCH(B3, Hazard_current_cycle!$B$3:$B$61, 0)), "") | D3: =IFERROR(INDEX(Exposure_LandUse!$E$3:$E$61, MATCH(B3, Exposure_LandUse!$B$3:$B$61, 0)), "") -> 0.068990692 | E3: =IFERROR(INDEX(Exposure_Population!$E$3:$E$61, MATCH(B3, Exposure_Population!$B$3:$B$61, 0)), "") -> 0.18343748 | F3: =IFERROR(INDEX(Exposure_Cattle!$D$3:$D$61, MATCH(B3, Exposure_Cattle!$B$3:$B$61, 0)), "") | G3: =IFERROR(INDEX(Exposure_WaterDemand!$D$3:$D$61, MATCH(B3, Exposure_WaterDemand!$B$3:$B$61, 0)), "") | H3: =IFERROR(AVERAGE(D3:G3), "") -> 0.12621409 | I3: =IFERROR(INDEX(Vulnerability_IPC!$E$3:$E$61, MATCH(B3, Vulnerability_IPC!$B$3:$B$61, 0)), "") -> 0.3 | J3: =IFERROR(C3*H3*I3, "") | K3: =IF(OR(J3="",NOT(ISNUMBER(J3))),"",IF(J3>=0.5,"Very High",IF(J3>=0.3,"High",IF(J3>=0.15,"Moderate","Low"))))
A4: 2 | B4: Lobamba | C4: =IFERROR(INDEX(Hazard_current_cycle!$E$3:$E$61, MATCH(B4, Hazard_current_cycle!$B$3:$B$61, 0)), "") | D4: =IFERROR(INDEX(Exposure_LandUse!$E$3:$E$61, MATCH(B4, Exposure_LandUse!$B$3:$B$61, 0)), "") -> 0.21340275 | E4: =IFERROR(INDEX(Exposure_Population!$E$3:$E$61, MATCH(B4, Exposure_Population!$B$3:$B$61, 0)), "") -> 0.9242977 | F4: =IFERROR(INDEX(Exposure_Cattle!$D$3:$D$61, MATCH(B4, Exposure_Cattle!$B$3:$B$61, 0)), "") | G4: =IFERROR(INDEX(Exposure_WaterDemand!$D$3:$D$61, MATCH(B4, Exposure_WaterDemand!$B$3:$B$61, 0)), "") | H4: =IFERROR(AVERAGE(D4:G4), "") -> 0.56885022 | I4: =IFERROR(INDEX(Vulnerability_IPC!$E$3:$E$61, MATCH(B4, Vulnerability_IPC!$B$3:$B$61, 0)), "") -> 0.3 | J4: =IFERROR(C4*H4*I4, "") | K4: =IF(OR(J4="",NOT(ISNUMBER(J4))),"",IF(J4>=0.5,"Very High",IF(J4>=0.3,"High",IF(J4>=0.15,"Moderate","Low"))))
A5: 3 | B5: Madlangempisi | C5: =IFERROR(INDEX(Hazard_current_cycle!$E$3:$E$61, MATCH(B5, Hazard_current_cycle!$B$3:$B$61, 0)), "") | D5: =IFERROR(INDEX(Exposure_LandUse!$E$3:$E$61, MATCH(B5, Exposure_LandUse!$B$3:$B$61, 0)), "") -> 0.15558239 | E5: =IFERROR(INDEX(Exposure_Population!$E$3:$E$61, MATCH(B5, Exposure_Population!$B$3:$B$61, 0)), "") -> 0.82243325 | F5: =IFERROR(INDEX(Exposure_Cattle!$D$3:$D$61, MATCH(B5, Exposure_Cattle!$B$3:$B$61, 0)), "") | G5: =IFERROR(INDEX(Exposure_WaterDemand!$D$3:$D$61, MATCH(B5, Exposure_WaterDemand!$B$3:$B$61, 0)), "") | H5: =IFERROR(AVERAGE(D5:G5), "") -> 0.48900782 | I5: =IFERROR(INDEX(Vulnerability_IPC!$E$3:$E$61, MATCH(B5, Vulnerability_IPC!$B$3:$B$61, 0)), "") -> 0.6 | J5: =IFERROR(C5*H5*I5, "") | K5: =IF(OR(J5="",NOT(ISNUMBER(J5))),"",IF(J5>=0.5,"Very High",IF(J5>=0.3,"High",IF(J5>=0.15,"Moderate","Low"))))
A6: 4 | B6: Maphalaleni | C6: =IFERROR(INDEX(Hazard_current_cycle!$E$3:$E$61, MATCH(B6, Hazard_current_cycle!$B$3:$B$61, 0)), "") | D6: =IFERROR(INDEX(Exposure_LandUse!$E$3:$E$61, MATCH(B6, Exposure_LandUse!$B$3:$B$61, 0)), "") -> 0.13971104 | E6: =IFERROR(INDEX(Exposure_Population!$E$3:$E$61, MATCH(B6, Exposure_Population!$B$3:$B$61, 0)), "") -> 0.27413987 | F6: =IFERROR(INDEX(Exposure_Cattle!$D$3:$D$61, MATCH(B6, Exposure_Cattle!$B$3:$B$61, 0)), "") | G6: =IFERROR(INDEX(Exposure_WaterDemand!$D$3:$D$61, MATCH(B6, Exposure_WaterDemand!$B$3:$B$61, 0)), "") | H6: =IFERROR(AVERAGE(D6:G6), "") -> 0.20692546 | I6: =IFERROR(INDEX(Vulnerability_IPC!$E$3:$E$61, MATCH(B6, Vulnerability_IPC!$B$3:$B$61, 0)), "") -> 0.3 | J6: =IFERROR(C6*H6*I6, "") | K6: =IF(OR(J6="",NOT(ISNUMBER(J6))),"",IF(J6>=0.5,"Very High",IF(J6>=0.3,"High",IF(J6>=0.15,"Moderate","Low"))))
A7: 5 | B7: Mayiwane | C7: =IFERROR(INDEX(Hazard_current_cycle!$E$3:$E$61, MATCH(B7, Hazard_current_cycle!$B$3:$B$61, 0)), "") | D7: =IFERROR(INDEX(Exposure_LandUse!$E$3:$E$61, MATCH(B7, Exposure_LandUse!$B$3:$B$61, 0)), "") -> 0.035343815 | E7: =IFERROR(INDEX(Exposure_Population!$E$3:$E$61, MATCH(B7, Exposure_Population!$B$3:$B$61, 0)), "") -> 0.35166279 | F7: =IFERROR(INDEX(Exposure_Cattle!$D$3:$D$61, MATCH(B7, Exposure_Cattle!$B$3:$B$61, 0)), "") | G7: =IFERROR(INDEX(Exposure_WaterDemand!$D$3:$D$61, MATCH(B7, Exposure_WaterDemand!$B$3:$B$61, 0)), "") | H7: =IFERROR(AVERAGE(D7:G7), "") -> 0.1935033 | I7: =IFERROR(INDEX(Vulnerability_IPC!$E$3:$E$61, MATCH(B7, Vulnerability_IPC!$B$3:$B$61, 0)), "") -> 0.6 | J7: =IFERROR(C7*H7*I7, "") | K7: =IF(OR(J7="",NOT(ISNUMBER(J7))),"",IF(J7>=0.5,"Very High",IF(J7>=0.3,"High",IF(J7>=0.15,"Moderate","Low"))))
A8: 6 | B8: Mbabane East | C8: =IFERROR(INDEX(Hazard_current_cycle!$E$3:$E$61, MATCH(B8, Hazard_current_cycle!$B$3:$B$61, 0)), "") | D8: =IFERROR(INDEX(Exposure_LandUse!$E$3:$E$61, MATCH(B8, Exposure_LandUse!$B$3:$B$61, 0)), "") -> 0.023346038 | E8: =IFERROR(INDEX(Exposure_Population!$E$3:$E$61, MATCH(B8, Exposure_Population!$B$3:$B$61, 0)), "") -> 1 | F8: =IFERROR(INDEX(Exposure_Cattle!$D$3:$D$61, MATCH(B8, Exposure_Cattle!$B$3:$B$61, 0)), "") | G8: =IFERROR(INDEX(Exposure_WaterDemand!$D$3:$D$61, MATCH(B8, Exposure_WaterDemand!$B$3:$B$61, 0)), "") | H8: =IFERROR(AVERAGE(D8:G8), "") -> 0.51167302 | I8: =IFERROR(INDEX(Vulnerability_IPC!$E$3:$E$61, MATCH(B8, Vulnerability_IPC!$B$3:$B$61, 0)), "") -> 0.3 | J8: =IFERROR(C8*H8*I8, "") | K8: =IF(OR(J8="",NOT(ISNUMBER(J8))),"",IF(J8>=0.5,"Very High",IF(J8>=0.3,"High",IF(J8>=0.15,"Moderate","Low"))))
A9: 7 | B9: Mbabane West | C9: =IFERROR(INDEX(Hazard_current_cycle!$E$3:$E$61, MATCH(B9, Hazard_current_cycle!$B$3:$B$61, 0)), "") | D9: =IFERROR(INDEX(Exposure_LandUse!$E$3:$E$61, MATCH(B9, Exposure_LandUse!$B$3:$B$61, 0)), "") -> 0.17083417 | E9: =IFERROR(INDEX(Exposure_Population!$E$3:$E$61, MATCH(B9, Exposure_Population!$B$3:$B$61, 0)), "") -> 0.36331602 | F9: =IFERROR(INDEX(Exposure_Cattle!$D$3:$D$61, MATCH(B9, Exposure_Cattle!$B$3:$B$61, 0)), "") | G9: =IFERROR(INDEX(Exposure_WaterDemand!$D$3:$D$61, MATCH(B9, Exposure_WaterDemand!$B$3:$B$61, 0)), "") | H9: =IFERROR(AVERAGE(D9:G9), "") -> 0.26707509 | I9: =IFERROR(INDEX(Vulnerability_IPC!$E$3:$E$61, MATCH(B9, Vulnerability_IPC!$B$3:$B$61, 0)), "") -> 0.3 | J9: =IFERROR(C9*H9*I9, "") | K9: =IF(OR(J9="",NOT(ISNUMBER(J9))),"",IF(J9>=0.5,"Very High",IF(J9>=0.3,"High",IF(J9>=0.15,"Moderate","Low"))))
A10: 8 | B10: Mhlangatane | C10: =IFERROR(INDEX(Hazard_current_cycle!$E$3:$E$61, MATCH(B10, Hazard_current_cycle!$B$3:$B$61, 0)), "") | D10: =IFERROR(INDEX(Exposure_LandUse!$E$3:$E$61, MATCH(B10, Exposure_LandUse!$B$3:$B$61, 0)), "") -> 0.28847857 | E10: =IFERROR(INDEX(Exposure_Population!$E$3:$E$61, MATCH(B10, Exposure_Population!$B$3:$B$61, 0)), "") -> 0.59958709 | F10: =IFERROR(INDEX(Exposure_Cattle!$D$3:$D$61, MATCH(B10, Exposure_Cattle!$B$3:$B$61, 0)), "") | G10: =IFERROR(INDEX(Exposure_WaterDemand!$D$3:$D$61, MATCH(B10, Exposure_WaterDemand!$B$3:$B$61, 0)), "") | H10: =IFERROR(AVERAGE(D10:G10), "") -> 0.44403283 | I10: =IFERROR(INDEX(Vulnerability_IPC!$E$3:$E$61, MATCH(B10, Vulnerability_IPC!$B$3:$B$61, 0)), "") -> 0.6 | J10: =IFERROR(C10*H10*I10, "") | K10: =IF(OR(J10="",NOT(ISNUMBER(J10))),"",IF(J10>=0.5,"Very High",IF(J10>=0.3,"High",IF(J10>=0.15,"Moderate","Low"))))
A11: 9 | B11: Ndzingeni | C11: =IFERROR(INDEX(Hazard_current_cycle!$E$3:$E$61, MATCH(B11, Hazard_current_cycle!$B$3:$B$61, 0)), "") | D11: =IFERROR(INDEX(Exposure_LandUse!$E$3:$E$61, MATCH(B11, Exposure_LandUse!$B$3:$B$61, 0)), "") -> 0.07930352 | E11: =IFERROR(INDEX(Exposure_Population!$E$3:$E$61, MATCH(B11, Exposure_Population!$B$3:$B$61, 0)), "") -> 0.51312656 | F11: =IFERROR(INDEX(Exposure_Cattle!$D$3:$D$61, MATCH(B11, Exposure_Cattle!$B$3:$B$61, 0)), "") | G11: =IFERROR(INDEX(Exposure_WaterDemand!$D$3:$D$61, MATCH(B11, Exposure_WaterDemand!$B$3:$B$61, 0)), "") | H11: =IFERROR(AVERAGE(D11:G11), "") -> 0.29621504 | I11: =IFERROR(INDEX(Vulnerability_IPC!$E$3:$E$61, MATCH(B11, Vulnerability_IPC!$B$3:$B$61, 0)), "") -> 0.3 | J11: =IFERROR(C11*H11*I11, "") | K11: =IF(OR(J11="",NOT(ISNUMBER(J11))),"",IF(J11>=0.5,"Very High",IF(J11>=0.3,"High",IF(J11>=0.15,"Moderate","Low"))))
A12: 10 | B12: Nkhaba | C12: =IFERROR(INDEX(Hazard_current_cycle!$E$3:$E$61, MATCH(B12, Hazard_current_cycle!$B$3:$B$61, 0)), "") | D12: =IFERROR(INDEX(Exposure_LandUse!$E$3:$E$61, MATCH(B12, Exposure_LandUse!$B$3:$B$61, 0)), "") -> 0.14669507 | E12: =IFERROR(INDEX(Exposure_Population!$E$3:$E$61, MATCH(B12, Exposure_Population!$B$3:$B$61, 0)), "") -> 0.37339889 | F12: =IFERROR(INDEX(Exposure_Cattle!$D$3:$D$61, MATCH(B12, Exposure_Cattle!$B$3:$B$61, 0)), "") | G12: =IFERROR(INDEX(Exposure_WaterDemand!$D$3:$D$61, MATCH(B12, Exposure_WaterDemand!$B$3:$B$61, 0)), "") | H12: =IFERROR(AVERAGE(D12:G12), "") -> 0.26004698 | I12: =IFERROR(INDEX(Vulnerability_IPC!$E$3:$E$61, MATCH(B12, Vulnerability_IPC!$B$3:$B$61, 0)), "") -> 0.3 | J12: =IFERROR(C12*H12*I12, "") | K12: =IF(OR(J12="",NOT(ISNUMBER(J12))),"",IF(J12>=0.5,"Very High",IF(J12>=0.3,"High",IF(J12>=0.15,"Moderate","Low"))))
A13: 11 | B13: Motshane | C13: =IFERROR(INDEX(Hazard_current_cycle!$E$3:$E$61, MATCH(B13, Hazard_current_cycle!$B$3:$B$61, 0)), "") | D13: =IFERROR(INDEX(Exposure_LandUse!$E$3:$E$61, MATCH(B13, Exposure_LandUse!$B$3:$B$61, 0)), "") -> 0.19067987 | E13: =IFERROR(INDEX(Exposure_Population!$E$3:$E$61, MATCH(B13, Exposure_Population!$B$3:$B$61, 0)), "") -> 0.67856177 | F13: =IFERROR(INDEX(Exposure_Cattle!$D$3:$D$61, MATCH(B13, Exposure_Cattle!$B$3:$B$61, 0)), "") | G13: =IFERROR(INDEX(Exposure_WaterDemand!$D$3:$D$61, MATCH(B13, Exposure_WaterDemand!$B$3:$B$61, 0)), "") | H13: =IFERROR(AVERAGE(D13:G13), "") -> 0.43462082 | I13: =IFERROR(INDEX(Vulnerability_IPC!$E$3:$E$61, MATCH(B13, Vulnerability_IPC!$B$3:$B$61, 0)), "") -> 0.3 | J13: =IFERROR(C13*H13*I13, "") | K13: =IF(OR(J13="",NOT(ISNUMBER(J13))),"",IF(J13>=0.5,"Very High",IF(J13>=0.3,"High",IF(J13>=0.15,"Moderate","Low"))))
A14: 12 | B14: Ntfonjeni | C14: =IFERROR(INDEX(Hazard_current_cycle!$E$3:$E$61, MATCH(B14, Hazard_current_cycle!$B$3:$B$61, 0)), "") | D14: =IFERROR(INDEX(Exposure_LandUse!$E$3:$E$61, MATCH(B14, Exposure_LandUse!$B$3:$B$61, 0)), "") -> 0.14024738 | E14: =IFERROR(INDEX(Exposure_Population!$E$3:$E$61, MATCH(B14, Exposure_Population!$B$3:$B$61, 0)), "") -> 0.53272656 | F14: =IFERROR(INDEX(Exposure_Cattle!$D$3:$D$61, MATCH(B14, Exposure_Cattle!$B$3:$B$61, 0)), "") | G14: =IFERROR(INDEX(Exposure_WaterDemand!$D$3:$D$61, MATCH(B14, Exposure_WaterDemand!$B$3:$B$61, 0)), "") | H14: =IFERROR(AVERAGE(D14:G14), "") -> 0.33648697 | I14: =IFERROR(INDEX(Vulnerability_IPC!$E$3:$E$61, MATCH(B14, Vulnerability_IPC!$B$3:$B$61, 0)), "") -> 0.3 | J14: =IFERROR(C14*H14*I14, "") | K14: =IF(OR(J14="",NOT(ISNUMBER(J14))),"",IF(J14>=0.5,"Very High",IF(J14>=0.3,"High",IF(J14>=0.15,"Moderate","Low"))))
... A61: 59 | B61: Zombodze Emuva | C61: =IFERROR(INDEX(Hazard_current_cycle!$E$3:$E$61, MATCH(B61, Hazard_current_cycle!$B$3:$B$61, 0)), "") | D61: =IFERROR(INDEX(Exposure_LandUse!$E$3:$E$61, MATCH(B61, Exposure_LandUse!$B$3:$B$61, 0)), "") -> 0.16579242 | E61: =IFERROR(INDEX(Exposure_Population!$E$3:$E$61, MATCH(B61, Exposure_Population!$B$3:$B$61, 0)), "") -> 0.21351051 | F61: =IFERROR(INDEX(Exposure_Cattle!$D$3:$D$61, MATCH(B61, Exposure_Cattle!$B$3:$B$61, 0)), "") | G61: =IFERROR(INDEX(Exposure_WaterDemand!$D$3:$D$61, MATCH(B61, Exposure_WaterDemand!$B$3:$B$61, 0)), "") | H61: =IFERROR(AVERAGE(D61:G61), "") -> 0.18965146 | I61: =IFERROR(INDEX(Vulnerability_IPC!$E$3:$E$61, MATCH(B61, Vulnerability_IPC!$B$3:$B$61, 0)), "") -> 0.3 | J61: =IFERROR(C61*H61*I61, "") | K61: =IF(OR(J61="",NOT(ISNUMBER(J61))),"",IF(J61>=0.5,"Very High",IF(J61>=0.3,"High",IF(J61>=0.15,"Moderate","Low"))))
